Workbook

Sheet dashboard
B2: description tâches | C2: achèvement | D2: Temps réel | E2: Temps estimé | F2: deadline | G2: ecart date | I2: =COUNTIF('to do'!$G$3:G$2024,TRUE)/(COUNTIF('to do'!$G$3:G$2024,TRUE)+COUNTIF('to do'!$G$3:G$2024,FALSE)) -> 0.15942029
B3: Environnement de travail mis en place | C3: =COUNTIFS('to do'!$A$3:$A$524,B3,'to do'!$G$3:$G$524,TRUE)/COUNTIF('to do'!$A$3:$A$524,B3) -> 1 | D3: =SUMIF('to do'!$A$2:$A$524,B3,'to do'!D$2:D$20045) -> 4.25 | E3: =SUMIF('to do'!$A$2:$A$524,B3,'to do'!E$2:E$20045) -> 4.25 | F3: 46255 | G3: =F3-TODAY() -> 1
B4: Documentaition initiale | C4: =COUNTIFS('to do'!$A$3:$A$524,B4,'to do'!$G$3:$G$524,TRUE)/COUNTIF('to do'!$A$3:$A$524,B4) -> 1 | D4: =SUMIF('to do'!$A$2:$A$524,B4,'to do'!D$2:D$20045) -> 8.25 | E4: =SUMIF('to do'!$A$2:$A$524,B4,'to do'!E$2:E$20045) -> 8.25 | F4: 46255 | G4: =F4-TODAY() -> 1
B5: Authentification / inscription | C5: =COUNTIFS('to do'!$A$3:$A$524,B5,'to do'!$G$3:$G$524,TRUE)/COUNTIF('to do'!$A$3:$A$524,B5) -> 0 | D5: =SUMIF('to do'!$A$2:$A$524,B5,'to do'!D$2:D$20045) -> 0 | E5: =SUMIF('to do'!$A$2:$A$524,B5,'to do'!E$2:E$20045) -> 10 | F5: 46255 | G5: =F5-TODAY() -> 1
B6: Gestion des comptes utilisateur (par rôle) | C6: =COUNTIFS('to do'!$A$3:$A$524,B6,'to do'!$G$3:$G$524,TRUE)/COUNTIF('to do'!$A$3:$A$524,B6) -> 0.21428571 | D6: =SUMIF('to do'!$A$2:$A$524,B6,'to do'!D$2:D$20045) -> 7.5 | E6: =SUMIF('to do'!$A$2:$A$524,B6,'to do'!E$2:E$20045) -> 39.5 | F6: 46262 | G6: =F6-TODAY() -> 8
B7: déploiement en préproduction | C7: =COUNTIFS('to do'!$A$3:$A$524,B7,'to do'!$G$3:$G$524,TRUE)/COUNTIF('to do'!$A$3:$A$524,B7) -> 0 | D7: =SUMIF('to do'!$A$2:$A$524,B7,'to do'!D$2:D$20045) -> 0 | E7: =SUMIF('to do'!$A$2:$A$524,B7,'to do'!E$2:E$20045) -> 16 | F7: 46262 | G7: =F7-TODAY() -> 8
B8: fonctionnalités commande | C8: =COUNTIFS('to do'!$A$3:$A$524,B8,'to do'!$G$3:$G$524,TRUE)/COUNTIF('to do'!$A$3:$A$524,B8) -> 0 | D8: =SUMIF('to do'!$A$2:$A$524,B8,'to do'!D$2:D$20045) -> 0 | E8: =SUMIF('to do'!$A$2:$A$524,B8,'to do'!E$2:E$20045) -> 32 | F8: 46276 | G8: =F8-TODAY() -> 22
B9: fonctionnalités livraison | C9: =COUNTIFS('to do'!$A$3:$A$524,B9,'to do'!$G$3:$G$524,TRUE)/COUNTIF('to do'!$A$3:$A$524,B9) -> 0 | D9: =SUMIF('to do'!$A$2:$A$524,B9,'to do'!D$2:D$20045) -> 0 | E9: =SUMIF('to do'!$A$2:$A$524,B9,'to do'!E$2:E$20045) -> 32 | F9: 46283 | G9: =F9-TODAY() -> 29
B10: rapport | C10: =COUNTIFS('to do'!$A$3:$A$524,B10,'to do'!$G$3:$G$524,TRUE)/COUNTIF('to do'!$A$3:$A$524,B10) -> 0 | D10: =SUMIF('to do'!$A$2:$A$524,B10,'to do'!D$2:D$20045) -> 2 | E10: =SUMIF('to do'!$A$2:$A$524,B10,'to do'!E$2:E$20045) -> 28 | F10: 46283 | G10: =F10-TODAY() -> 29
B11: total | D11: =SUM(D3:D10) -> 22 | E11: =SUM(E3:E10) -> 170
B13: Sprints | C13: achèvement | D13: Temps réel | E13: Temps estimé | F13: fin du sprint | G13: ecart date
B14: 0 | C14: =COUNTIFS('to do'!$C$3:$C$524,B14,'to do'!$G$3:$G$524,TRUE)/COUNTIF('to do'!$C$3:$C$524,B14) -> 0.64705882 | D14: =SUMIF('to do'!$C$2:$C$524,B14,'to do'!D$2:D$20045) -> 22 | E14: =SUMIF('to do'!$C$2:$C$524,B14,'to do'!E$2:E$20045) -> 34 | F14: 46255 | G14: =F14-TODAY() -> 1
B15: 1 | C15: =COUNTIFS('to do'!$C$3:$C$524,B15,'to do'!$G$3:$G$524,TRUE)/COUNTIF('to do'!$C$3:$C$524,B15) -> 0 | D15: =SUMIF('to do'!$C$2:$C$524,B15,'to do'!D$2:D$20045) -> 0 | E15: =SUMIF('to do'!$C$2:$C$524,B15,'to do'!E$2:E$20045) -> 36 | F15: 46262 | G15: =F15-TODAY() -> 8
B16: 2 | C16: =COUNTIFS('to do'!$C$3:$C$524,B16,'to do'!$G$3:$G$524,TRUE)/COUNTIF('to do'!$C$3:$C$524,B16) -> 0 | D16: =SUMIF('to do'!$C$2:$C$524,B16,'to do'!D$2:D$20045) -> 0 | E16: =SUMIF('to do'!$C$2:$C$524,B16,'to do'!E$2:E$20045) -> 34 | F16: 46269 | G16: =F16-TODAY() -> 15
B17: 3 | C17: =COUNTIFS('to do'!$C$3:$C$524,B17,'to do'!$G$3:$G$524,TRUE)/COUNTIF('to do'!$C$3:$C$524,B17) -> 0 | D17: =SUMIF('to do'!$C$2:$C$524,B17,'to do'!D$2:D$20045) -> 0 | E17: =SUMIF('to do'!$C$2:$C$524,B17,'to do'!E$2:E$20045) -> 34 | F17: 46276 | G17: =F17-TODAY() -> 22
B18: 4 | C18: =COUNTIFS('to do'!$C$3:$C$524,B18,'to do'!$G$3:$G$524,TRUE)/COUNTIF('to do'!$C$3:$C$524,B18) -> 0 | D18: =SUMIF('to do'!$C$2:$C$524,B18,'to do'!D$2:D$20045) -> 0 | E18: =SUMIF('to do'!$C$2:$C$524,B18,'to do'!E$2:E$20045) -> 32 | F18: 46283 | G18: =F18-TODAY() -> 29
B19: total | D19: =SUM(D12:D18) -> 22 | E19: =SUM(E14:E18) -> 170

Sheet to do
A1: description tâche | B1: description sous-tâche | C1: sprint | D1: Temps réel | E1: Temps estimé | F1: commentaire | G1: done
A2: Environnement de travail mis en place | B2: lire les consigne cahier des charges et écouter à la séance d'information | C2: 0 | D2: 1.5 | E2: 1.5 | G2: TRUE
A3: Environnement de travail mis en place | B3: mettre en place le github | C3: 0 | D3: 0.25 | E3: 0.25 | G3: TRUE
A4: Documentaition initiale | B4: configurer et remplir le journal de travail | C4: 0 | D4: 0.25 | E4: 0.25 | G4: TRUE
A5: Environnement de travail mis en place | B5: Réunion au sujet de la donnée du travail de diplôme | C5: 0 | D5: 1.25 | E5: 1.25 | G5: TRUE
A6: Environnement de travail mis en place | B6: Démarrer officialement le projet avec la mandante | C6: 0 | D6: 1.25 | E6: 1.25 | G6: TRUE
A7: Documentaition initiale | B7: planification | C7: 0 | D7: 4 | E7: 2 | G7: TRUE
A8: rapport | B8: débuter le rapport de diplôme | C8: 0 | D8: 2 | E8: 4 | G8: FALSE
A9: Authentification / inscription | B9: faire la page front de d'authentification simple | C9: 0 | E9: 2 | G9: FALSE
A10: Authentification / inscription | B10: faire la partie back d'authentification simple | C10: 0 | E10: 2 | G10: FALSE
A11: Authentification / inscription | B11: faire la page front de l'enregistrement simple | C11: 0 | E11: 2 | G11: FALSE
A12: Authentification / inscription | B12: faire la partie back de l'enregistrement simple | C12: 0 | E12: 2 | G12: FALSE
A13: Authentification / inscription | B13: faire la page d'accueil initial | C13: 0 | E13: 2 | G13: FALSE
A14: Documentaition initiale | B14: Ecrire le template de la definition of done | C14: 0 | E14: 2 | G14: TRUE
A15: Gestion des comptes utilisateur (par rôle) | B15: conception du MCD compte utilisateur | C15: 0 | D15: 3 | E15: 2 | G15: TRUE
A16: Gestion des comptes utilisateur (par rôle) | B16: conception maquette | C16: 0 | D16: 3.5 | E16: 3.5 | G16: TRUE
A17: Gestion des comptes utilisateur (par rôle) | B17: conception du diagramme de uses cases | C17: 0 | D17: 1 | E17: 2 | G17: TRUE
A18: Documentaition initiale | B18: conception du diagramme de classe | C18: 0 | D18: 2 | E18: 2 | G18: TRUE
A19: Documentaition initiale | B19: conception du diagramme de micro-service | C19: 0 | D19: 2 | E19: 2 | G19: TRUE
A20: Gestion des comptes utilisateur (par rôle) | B20: faire les différent dashboard de rôle | C20: 1 | E20: 2 | G20: FALSE
A21: Gestion des comptes utilisateur (par rôle) | B21: faire la partie gestion du compte front (CRUD) (clients) | C21: 1 | E21: 2 | G21: FALSE
A22: Gestion des comptes utilisateur (par rôle) | B22: faire la partie gestion du compte back (CRUD) (clients) | C22: 1 | E22: 4 | G22: FALSE
A23: Gestion des comptes utilisateur (par rôle) | B23: faire la partie gestion du compte front (CRUD) (restaurant partenaire) | C23: 1 | E23: 2 | G23: FALSE
A24: Gestion des comptes utilisateur (par rôle) | B24: faire la partie gestion du compte back (CRUD) (restaurant partenaire) | C24: 1 | E24: 4 | G24: FALSE
A25: Gestion des comptes utilisateur (par rôle) | B25: faire la partie gestion du compte front (CRUD) (modérateur) | C25: 1 | E25: 2 | G25: FALSE
A26: Gestion des comptes utilisateur (par rôle) | B26: faire la partie gestion du compte back (CRUD) (modérateur) | C26: 1 | E26: 4 | G26: FALSE
A27: Gestion des comptes utilisateur (par rôle) | B27: faire la partie gestion du compte front (CRUD) (administrateur) | C27: 1 | E27: 2 | G27: FALSE
A28: Gestion des comptes utilisateur (par rôle) | B28: faire la partie gestion du compte back (CRUD) (administrateur) | C28: 1 | E28: 4 | G28: FALSE
A29: Gestion des comptes utilisateur (par rôle) | B29: faire la partie gestion du compte front (CRUD) (livreur) | C29: 1 | E29: 2 | G29: FALSE
A30: Gestion des comptes utilisateur (par rôle) | B30: faire la partie gestion du compte back (CRUD) (livreur) | C30: 1 | E30: 4 | G30: FALSE
A31: déploiement en préproduction | B31: mettre en place la dockerisation | C31: 1 | E31: 4 | G31: FALSE
... A53: fonctionnalités livraison | B53: Faire le diagranne de séquence correspondant au processus de livraison | C53: 3 | E53: 2 | G53: FALSE
G54: FALSE
G55: FALSE
G56: FALSE
G57: FALSE
G58: FALSE
G59: FALSE
G60: FALSE
G61: FALSE
...
